<sdf version='1.4'>
  <world name='default'>
    <light name='sun' type='directional'>
      <cast_shadows>1</cast_shadows>
      <pose>0 0 10 0 -0 0</pose>
      <diffuse>0.8 0.8 0.8 1</diffuse>
      <specular>0.2 0.2 0.2 1</specular>
      <attenuation>
        <range>1000</range>
        <constant>0.9</constant>
        <linear>0.01</linear>
        <quadratic>0.001</quadratic>
      </attenuation>
      <direction>-0.5 0.1 -0.9</direction>
    </light>
    <model name='ground_plane'>
      <static>1</static>
      <link name='link'>
        <collision name='collision'>
          <geometry>
            <plane>
              <normal>0 0 1</normal>
              <size>100 100</size>
            </plane>
          </geometry>
          <surface>
            <friction>
              <ode>
                <mu>100</mu>
                <mu2>50</mu2>
              </ode>
            </friction>
            <bounce/>
            <contact>
              <ode/>
            </contact>
          </surface>
          <max_contacts>10</max_contacts>
        </collision>
        <visual name='visual'>
          <cast_shadows>0</cast_shadows>
          <geometry>
            <plane>
              <normal>0 0 1</normal>
              <size>100 100</size>
            </plane>
          </geometry>
          <material>
            <script>
              <uri>file://media/materials/scripts/gazebo.material</uri>
              <name>Gazebo/Grey</name>
            </script>
          </material>
        </visual>
        <velocity_decay>
          <linear>0</linear>
          <angular>0</angular>
        </velocity_decay>
        <self_collide>0</self_collide>
        <kinematic>0</kinematic>
        <gravity>1</gravity>
      </link>
    </model>
    <physics type='ode'>
      <max_step_size>0.001</max_step_size>
      <real_time_factor>1</real_time_factor>
      <real_time_update_rate>1000</real_time_update_rate>
      <gravity>0 0 -9.8</gravity>
    </physics>
    <scene>
      <ambient>0.4 0.4 0.4 1</ambient>
      <background>0.7 0.7 0.7 1</background>
      <shadows>1</shadows>
    </scene>
    <spherical_coordinates>
      <surface_model>EARTH_WGS84</surface_model>
      <latitude_deg>0</latitude_deg>
      <longitude_deg>0</longitude_deg>
      <elevation>0</elevation>
      <heading_deg>0</heading_deg>
    </spherical_coordinates>
    <light name='sun_0' type='directional'>
      <cast_shadows>1</cast_shadows>
      <pose>3.4607 -3 10 0 -0 0</pose>
      <diffuse>0.8 0.8 0.8 1</diffuse>
      <specular>0.2 0.2 0.2 1</specular>
      <attenuation>
        <range>1000</range>
        <constant>0.9</constant>
        <linear>0.01</linear>
        <quadratic>0.001</quadratic>
      </attenuation>
      <direction>-0.5 0.1 -0.9</direction>
    </light>
    <state world_name='default'>
      <sim_time>16627 337000000</sim_time>
      <real_time>47 750826281</real_time>
      <wall_time>1490987584 111574093</wall_time>
      <model name='Altorfer_f1'>
        <pose>0 0 0 0 -0 0</pose>
        <link name='Wall_0'>
          <pose>7.715 0 0 0 -0 0</pose>
          <velocity>0 0 0 0 -0 0</velocity>
          <acceleration>0 0 0 0 -0 0</acceleration>
          <wrench>0 0 0 0 -0 0</wrench>
        </link>
        <link name='Wall_11'>
          <pose>10.11 -2.264 0 0 -0 3.14159</pose>
          <velocity>0 0 0 0 -0 0</velocity>
          <acceleration>0 0 0 0 -0 0</acceleration>
          <wrench>0 0 0 0 -0 0</wrench>
        </link>
        <link name='Wall_13'>
          <pose>7.631 -5.639 0 0 0 -1.5708</pose>
          <velocity>0 0 0 0 -0 0</velocity>
          <acceleration>0 0 0 0 -0 0</acceleration>
          <wrench>0 0 0 0 -0 0</wrench>
        </link>
        <link name='Wall_15'>
          <pose>-0.038 -4.5505 0 0 0 -1.5708</pose>
          <velocity>0 0 0 0 -0 0</velocity>
          <acceleration>0 0 0 0 -0 0</acceleration>
          <wrench>0 0 0 0 -0 0</wrench>
        </link>
        <link name='Wall_16'>
          <pose>3.7965 -9.124 0 0 -0 0</pose>
          <velocity>0 0 0 0 -0 0</velocity>
          <acceleration>0 0 0 0 -0 0</acceleration>
          <wrench>0 0 0 0 -0 0</wrench>
        </link>
        <link name='Wall_18'>
          <pose>2.81106 -2.29895 0 0 -0 3.14159</pose>
          <velocity>0 0 0 0 -0 0</velocity>
          <acceleration>0 0 0 0 -0 0</acceleration>
          <wrench>0 0 0 0 -0 0</wrench>
        </link>
        <link name='Wall_5'>
          <pose>15.549 -2.374 0 0 -0 1.5708</pose>
          <velocity>0 0 0 0 -0 0</velocity>
          <acceleration>0 0 0 0 -0 0</acceleration>
          <wrench>0 0 0 0 -0 0</wrench>
        </link>
        <link name='Wall_7'>
          <pose>14.021 -4.762 0 0 -0 0</pose>
          <velocity>0 0 0 0 -0 0</velocity>
          <acceleration>0 0 0 0 -0 0</acceleration>
          <wrench>0 0 0 0 -0 0</wrench>
        </link>
        <link name='Wall_9'>
          <pose>12.52 -3.511 0 0 -0 1.5708</pose>
          <velocity>0 0 0 0 -0 0</velocity>
          <acceleration>0 0 0 0 -0 0</acceleration>
          <wrench>0 0 0 0 -0 0</wrench>
        </link>
      </model>
      <model name='ground_plane'>
        <pose>0 0 0 0 -0 0</pose>
        <link name='link'>
          <pose>0 0 0 0 -0 0</pose>
          <velocity>0 0 0 0 -0 0</velocity>
          <acceleration>0 0 0 0 -0 0</acceleration>
          <wrench>0 0 0 0 -0 0</wrench>
        </link>
      </model>
      <model name='my_robot'>
        <pose>2.71224 -8.75712 0.170003 -1.1e-05 3e-06 1.48569</pose>
        <link name='c1'>
          <pose>2.71224 -8.75712 0.470003 -1.1e-05 3e-06 1.48569</pose>
          <velocity>-8e-05 0.001122 0.001333 -0.002976 0.000673 -7.9e-05</velocity>
          <acceleration>0 0 0 0 -0 0</acceleration>
          <wrench>0 0 0 0 -0 0</wrench>
        </link>
        <link name='c2'>
          <pose>2.71224 -8.75712 0.770003 -1.1e-05 3e-06 1.48569</pose>
          <velocity>0.00051 0.001975 0.001332 -0.002931 0.00111 -0.000265</velocity>
          <acceleration>0 0 0 0 -0 0</acceleration>
          <wrench>0 0 0 0 -0 0</wrench>
        </link>
        <link name='c3'>
          <pose>2.71224 -8.75712 1.07 -1.1e-05 3e-06 1.48569</pose>
          <velocity>0.001556 0.00277 0.001332 -0.00286 0.001773 0.000151</velocity>
          <acceleration>0 0 0 0 -0 0</acceleration>
          <wrench>0 0 0 0 -0 0</wrench>
        </link>
        <link name='c4'>
          <pose>2.59121 -8.64643 0.630002 -1e-05 3e-06 1.48569</pose>
          <velocity>0.000895 0.001501 0.00135 -0.002748 0.002548 -0.000545</velocity>
          <acceleration>0 0 0 0 -0 0</acceleration>
          <wrench>0 0 0 0 -0 0</wrench>
        </link>
        <link name='c5'>
          <pose>2.57421 -8.8457 0.630002 -1e-05 3e-06 1.48569</pose>
          <velocity>0.000873 0.001484 0.001938 -0.002701 0.002664 0.000243</velocity>
          <acceleration>0 0 0 0 -0 0</acceleration>
          <wrench>0 0 0 0 -0 0</wrench>
        </link>
        <link name='c6'>
          <pose>2.83327 -8.86781 0.630005 -1e-05 3e-06 1.48569</pose>
          <velocity>0.00079 0.001441 0.001321 -0.002668 0.002594 -0.000467</velocity>
          <acceleration>0 0 0 0 -0 0</acceleration>
          <wrench>0 0 0 0 -0 0</wrench>
        </link>
        <link name='c7'>
          <pose>2.85027 -8.66853 0.630004 -1e-05 3e-06 1.48569</pose>
          <velocity>0.000678 0.001452 0.000784 -0.002675 0.002366 -0.000409</velocity>
          <acceleration>0 0 0 0 -0 0</acceleration>
          <wrench>0 0 0 0 -0 0</wrench>
        </link>
        <link name='chassis'>
          <pose>2.71224 -8.75712 0.170003 -1.1e-05 3e-06 1.48569</pose>
          <velocity>-0.000369 0.00024 0.001333 -0.002988 0.000508 -0.000116</velocity>
          <acceleration>0 0 0 0 -0 0</acceleration>
          <wrench>0 0 0 0 -0 0</wrench>
        </link>
        <link name='hokuyo'>
          <pose>2.71224 -8.75712 0.170003 -1e-05 3e-06 1.48569</pose>
          <velocity>-0.000364 0.000241 0.001333 -0.003191 -0.000793 0.000273</velocity>
          <acceleration>0 0 0 0 -0 0</acceleration>
          <wrench>0 0 0 0 -0 0</wrench>
        </link>
        <link name='kinect::link'>
          <pose>2.72669 -8.58773 0.820003 -1e-05 3e-06 1.48569</pose>
          <velocity>-0.000213 0.002203 0.000818 -0.003109 -0.0004 -0.000336</velocity>
          <acceleration>0 0 0 0 -0 0</acceleration>
          <wrench>0 0 0 0 -0 0</wrench>
        </link>
        <link name='left_front_wheel'>
          <pose>2.5226 -8.61548 0.110002 -1.57088 1.00751 -1.65589</pose>
          <velocity>-9e-06 0.000144 0.001287 -0.001249 -4.6e-05 -0.000204</velocity>
          <acceleration>0 0 0 0 -0 0</acceleration>
          <wrench>0 0 0 0 -0 0</wrench>
        </link>
        <link name='left_rear_wheel'>
          <pose>2.50135 -8.86458 0.110003 -1.57088 -0.510335 -1.65591</pose>
          <velocity>-0.000126 -1e-06 0.001156 3.6e-05 -0.001114 -7e-05</velocity>
          <acceleration>0 0 0 0 -0 0</acceleration>
          <wrench>0 0 0 0 -0 0</wrench>
        </link>
        <link name='right_front_wheel'>
          <pose>2.92314 -8.64966 0.110005 -1.57088 -0.068658 -1.6559</pose>
          <velocity>-0.000293 4.1e-05 0.000711 -0.001046 0.001745 -0.000158</velocity>
          <acceleration>0 0 0 0 -0 0</acceleration>
          <wrench>0 0 0 0 -0 0</wrench>
        </link>
        <link name='right_rear_wheel'>
          <pose>2.90189 -8.89875 0.110006 1.57069 -0.386927 1.48569</pose>
          <velocity>-0.000331 -0.000109 0.001655 0.001285 0.000701 -0.000197</velocity>
          <acceleration>0 0 0 0 -0 0</acceleration>
          <wrench>0 0 0 0 -0 0</wrench>
        </link>
      </model>
      <model name='person_standing_0'>
        <pose>6.07432 -5.61053 0.005575 0.017448 0.003113 0.207261</pose>
        <link name='link'>
          <pose>6.07432 -5.61053 0.005575 0.017448 0.003113 0.207261</pose>
          <velocity>-0.316318 -0.4393 0.186519 0.605659 0.184043 1.44827</velocity>
          <acceleration>0 0 0 0 -0 0</acceleration>
          <wrench>0 0 0 0 -0 0</wrench>
        </link>
      </model>
      <model name='person_standing_1'>
        <pose>1.14525 -6.62626 0.005453 0.017013 0.003097 0.176707</pose>
        <link name='link'>
          <pose>1.14525 -6.62626 0.005453 0.017013 0.003097 0.176707</pose>
          <velocity>-0.321379 -0.419865 0.183695 0.595561 0.160723 1.41527</velocity>
          <acceleration>0 0 0 0 -0 0</acceleration>
          <wrench>0 0 0 0 -0 0</wrench>
        </link>
      </model>
      <model name='person_standing_2'>
        <pose>14.2267 -2.1117 0.004539 0.014339 0.002386 -2.80219</pose>
        <link name='link'>
          <pose>14.2267 -2.1117 0.004539 0.014339 0.002386 -2.80219</pose>
          <velocity>0.199784 0.372573 0.141967 -0.443467 -0.197317 1.13235</velocity>
          <acceleration>0 0 0 0 -0 0</acceleration>
          <wrench>0 0 0 0 -0 0</wrench>
        </link>
      </model>
      <model name='person_standing_3'>
        <pose>6.77669 -1.09273 0.004637 0.014661 0.002426 -1.51648</pose>
        <link name='link'>
          <pose>6.77669 -1.09273 0.004637 0.014661 0.002426 -1.51648</pose>
          <velocity>-0.34602 0.340624 0.166407 0.081838 -0.556988 1.30017</velocity>
          <acceleration>0 0 0 0 -0 0</acceleration>
          <wrench>0 0 0 0 -0 0</wrench>
        </link>
      </model>
      <model name='person_standing_4'>
        <pose>5.77968 -3.5133 0.005765 0.02028 -0.000755 -0.755238</pose>
        <link name='link'>
          <pose>5.77968 -3.5133 0.005765 0.02028 -0.000755 -0.755238</pose>
          <velocity>0.016384 -0.24242 0.205402 0.539733 -0.512544 -0.645186</velocity>
          <acceleration>0 0 0 0 -0 0</acceleration>
          <wrench>0 0 0 0 -0 0</wrench>
        </link>
      </model>
    </state>
    <gui fullscreen='0'>
      <camera name='user_camera'>
        <pose>8.09664 -5.25166 46.5195 6.0191e-16 1.5698 -3.12505</pose>
        <view_controller>orbit</view_controller>
      </camera>
    </gui>
    <model name='Altorfer_f1'>
      <link name='Wall_0'>
        <collision name='Wall_0_Collision'>
          <geometry>
            <box>
              <size>15.7 0.2 3</size>
            </box>
          </geometry>
          <pose>0 0 1.5 0 -0 0</pose>
          <max_contacts>10</max_contacts>
          <surface>
            <bounce/>
            <friction>
              <ode/>
            </friction>
            <contact>
              <ode/>
            </contact>
          </surface>
        </collision>
        <visual name='Wall_0_Visual'>
          <pose>0 0 1.5 0 -0 0</pose>
          <geometry>
            <box>
              <size>15.7 0.2 3</size>
            </box>
          </geometry>
          <material>
            <script>
              <uri>file://media/materials/scripts/gazebo.material</uri>
              <name>Gazebo/Grey</name>
            </script>
          </material>
        </visual>
        <velocity_decay>
          <linear>0</linear>
          <angular>0</angular>
        </velocity_decay>
        <pose>7.715 0 0 0 -0 0</pose>
        <self_collide>0</self_collide>
        <kinematic>0</kinematic>
        <gravity>1</gravity>
      </link>
      <link name='Wall_11'>
        <collision name='Wall_11_Collision'>
          <geometry>
            <box>
              <size>5.02 0.2 3</size>
            </box>
          </geometry>
          <pose>0 0 1.5 0 -0 0</pose>
          <max_contacts>10</max_contacts>
          <surface>
            <bounce/>
            <friction>
              <ode/>
            </friction>
            <contact>
              <ode/>
            </contact>
          </surface>
        </collision>
        <visual name='Wall_11_Visual'>
          <pose>0 0 1.5 0 -0 0</pose>
          <geometry>
            <box>
              <size>5.02 0.2 3</size>
            </box>
          </geometry>
          <material>
            <script>
              <uri>file://media/materials/scripts/gazebo.material</uri>
              <name>Gazebo/Grey</name>
            </script>
          </material>
        </visual>
        <velocity_decay>
          <linear>0</linear>
          <angular>0</angular>
        </velocity_decay>
        <pose>10.11 -2.264 0 0 -0 3.14159</pose>
        <self_collide>0</self_collide>
        <kinematic>0</kinematic>
        <gravity>1</gravity>
      </link>
      <link name='Wall_13'>
        <collision name='Wall_13_Collision'>
          <geometry>
            <box>
              <size>6.95 0.2 3</size>
            </box>
          </geometry>
          <pose>0 0 1.5 0 -0 0</pose>
          <max_contacts>10</max_contacts>
          <surface>
            <bounce/>
            <friction>
              <ode/>
            </friction>
            <contact>
              <ode/>
            </contact>
          </surface>
        </collision>
        <visual name='Wall_13_Visual'>
          <pose>0 0 1.5 0 -0 0</pose>
          <geometry>
            <box>
              <size>6.95 0.2 3</size>
            </box>
          </geometry>
          <material>
            <script>
              <uri>file://media/materials/scripts/gazebo.material</uri>
              <name>Gazebo/Grey</name>
            </script>
          </material>
        </visual>
        <velocity_decay>
          <linear>0</linear>
          <angular>0</angular>
        </velocity_decay>
        <pose>7.631 -5.639 0 0 0 -1.5708</pose>
        <self_collide>0</self_collide>
        <kinematic>0</kinematic>
        <gravity>1</gravity>
      </link>
      <link name='Wall_15'>
        <pose>-0.038 -4.5505 0 0 0 -1.5708</pose>
        <visual name='Wall_15_Visual_0'>
          <pose>-3.23935 0 1.5 0 -0 0</pose>
          <geometry>
            <box>
              <size>2.86777 0.2 3</size>
            </box>
          </geometry>
          <material>
            <script>
              <uri>file://media/materials/scripts/gazebo.material</uri>
              <name>Gazebo/Grey</name>
            </script>
          </material>
        </visual>
        <collision name='Wall_15_Collision_0'>
          <geometry>
            <box>
              <size>2.86777 0.2 3</size>
            </box>
          </geometry>
          <pose>-3.23935 0 1.5 0 -0 0</pose>
          <max_contacts>10</max_contacts>
          <surface>
            <bounce/>
            <friction>
              <ode/>
            </friction>
            <contact>
              <ode/>
            </contact>
          </surface>
        </collision>
        <visual name='Wall_15_Visual_1'>
          <pose>1.43389 0 0.25 0 -0 0</pose>
          <geometry>
            <box>
              <size>6.47871 0.2 0.5</size>
            </box>
          </geometry>
          <material>
            <script>
              <uri>file://media/materials/scripts/gazebo.material</uri>
              <name>Gazebo/Grey</name>
            </script>
          </material>
        </visual>
        <collision name='Wall_15_Collision_1'>
          <geometry>
            <box>
              <size>6.47871 0.2 0.5</size>
            </box>
          </geometry>
          <pose>1.43389 0 0.25 0 -0 0</pose>
          <max_contacts>10</max_contacts>
          <surface>
            <bounce/>
            <friction>
              <ode/>
            </friction>
            <contact>
              <ode/>
            </contact>
          </surface>
        </collision>
        <visual name='Wall_15_Visual_2'>
          <pose>-0.035282 0 1.75 0 -0 0</pose>
          <geometry>
            <box>
              <size>0.540368 0.2 2.5</size>
            </box>
          </geometry>
          <material>
            <script>
              <uri>file://media/materials/scripts/gazebo.material</uri>
              <name>Gazebo/Grey</name>
            </script>
          </material>
        </visual>
        <collision name='Wall_15_Collision_2'>
          <geometry>
            <box>
              <size>0.540368 0.2 2.5</size>
            </box>
          </geometry>
          <pose>-0.035282 0 1.75 0 -0 0</pose>
          <max_contacts>10</max_contacts>
          <surface>
            <bounce/>
            <friction>
              <ode/>
            </friction>
            <contact>
              <ode/>
            </contact>
          </surface>
        </collision>
        <visual name='Wall_15_Visual_3'>
          <pose>2.07544 0 1.75 0 -0 0</pose>
          <geometry>
            <box>
              <size>0.681083 0.2 2.5</size>
            </box>
          </geometry>
          <material>
            <script>
              <uri>file://media/materials/scripts/gazebo.material</uri>
              <name>Gazebo/Grey</name>
            </script>
          </material>
        </visual>
        <collision name='Wall_15_Collision_3'>
          <geometry>
            <box>
              <size>0.681083 0.2 2.5</size>
            </box>
          </geometry>
          <pose>2.07544 0 1.75 0 -0 0</pose>
          <max_contacts>10</max_contacts>
          <surface>
            <bounce/>
            <friction>
              <ode/>
            </friction>
            <contact>
              <ode/>
            </contact>
          </surface>
        </collision>
        <visual name='Wall_15_Visual_4'>
          <pose>4.29461 0 1.75 0 -0 0</pose>
          <geometry>
            <box>
              <size>0.757254 0.2 2.5</size>
            </box>
          </geometry>
          <material>
            <script>
              <uri>file://media/materials/scripts/gazebo.material</uri>
              <name>Gazebo/Grey</name>
            </script>
          </material>
        </visual>
        <collision name='Wall_15_Collision_4'>
          <geometry>
            <box>
              <size>0.757254 0.2 2.5</size>
            </box>
          </geometry>
          <pose>4.29461 0 1.75 0 -0 0</pose>
          <max_contacts>10</max_contacts>
          <surface>
            <bounce/>
            <friction>
              <ode/>
            </friction>
            <contact>
              <ode/>
            </contact>
          </surface>
        </collision>
        <visual name='Wall_15_Visual_5'>
          <pose>-1.05547 0 2.75 0 -0 0</pose>
          <geometry>
            <box>
              <size>1.5 0.2 0.5</size>
            </box>
          </geometry>
          <material>
            <script>
              <uri>file://media/materials/scripts/gazebo.material</uri>
              <name>Gazebo/Grey</name>
            </script>
          </material>
        </visual>
        <collision name='Wall_15_Collision_5'>
          <geometry>
            <box>
              <size>1.5 0.2 0.5</size>
            </box>
          </geometry>
          <pose>-1.05547 0 2.75 0 -0 0</pose>
          <max_contacts>10</max_contacts>
          <surface>
            <bounce/>
            <friction>
              <ode/>
            </friction>
            <contact>
              <ode/>
            </contact>
          </surface>
        </collision>
        <visual name='Wall_15_Visual_6'>
          <pose>0.984902 0 2.75 0 -0 0</pose>
          <geometry>
            <box>
              <size>1.5 0.2 0.5</size>
            </box>
          </geometry>
          <material>
            <script>
              <uri>file://media/materials/scripts/gazebo.material</uri>
              <name>Gazebo/Grey</name>
            </script>
          </material>
        </visual>
        <collision name='Wall_15_Collision_6'>
          <geometry>
            <box>
              <size>1.5 0.2 0.5</size>
            </box>
          </geometry>
          <pose>0.984902 0 2.75 0 -0 0</pose>
          <max_contacts>10</max_contacts>
          <surface>
            <bounce/>
            <friction>
              <ode/>
            </friction>
            <contact>
              <ode/>
            </contact>
          </surface>
        </collision>
        <visual name='Wall_15_Visual_7'>
          <pose>3.16599 0 2.75 0 -0 0</pose>
          <geometry>
            <box>
              <size>1.5 0.2 0.5</size>
            </box>
          </geometry>
          <material>
            <script>
              <uri>file://media/materials/scripts/gazebo.material</uri>
              <name>Gazebo/Grey</name>
            </script>
          </material>
        </visual>
        <collision name='Wall_15_Collision_7'>
          <geometry>
            <box>
              <size>1.5 0.2 0.5</size>
            </box>
          </geometry>
          <pose>3.16599 0 2.75 0 -0 0</pose>
          <max_contacts>10</max_contacts>
          <surface>
            <bounce/>
            <friction>
              <ode/>
            </friction>
            <contact>
              <ode/>
            </contact>
          </surface>
        </collision>
        <velocity_decay>
          <linear>0</linear>
          <angular>0</angular>
        </velocity_decay>
        <self_collide>0</self_collide>
        <kinematic>0</kinematic>
        <gravity>1</gravity>
      </link>
      <link name='Wall_16'>
        <pose>3.7965 -9.124 0 0 -0 0</pose>
        <visual name='Wall_16_Visual_0'>
          <pose>-2.71184 0 1.5 0 -0 0</pose>
          <geometry>
            <box>
              <size>2.4453 0.2 3</size>
            </box>
          </geometry>
          <material>
            <script>
              <uri>file://media/materials/scripts/gazebo.material</uri>
              <name>Gazebo/Grey</name>
            </script>
          </material>
        </visual>
        <collision name='Wall_16_Collision_0'>
          <geometry>
            <box>
              <size>2.4453 0.2 3</size>
            </box>
          </geometry>
          <pose>-2.71184 0 1.5 0 -0 0</pose>
          <max_contacts>10</max_contacts>
          <surface>
            <bounce/>
            <friction>
              <ode/>
            </friction>
            <contact>
              <ode/>
            </contact>
          </surface>
        </collision>
        <visual name='Wall_16_Visual_1'>
          <pose>1.22265 0 0.25 0 -0 0</pose>
          <geometry>
            <box>
              <size>5.42367 0.2 0.5</size>
            </box>
          </geometry>
          <material>
            <script>
              <uri>file://media/materials/scripts/gazebo.material</uri>
              <name>Gazebo/Grey</name>
            </script>
          </material>
        </visual>
        <collision name='Wall_16_Collision_1'>
          <geometry>
            <box>
              <size>5.42367 0.2 0.5</size>
            </box>
          </geometry>
          <pose>1.22265 0 0.25 0 -0 0</pose>
          <max_contacts>10</max_contacts>
          <surface>
            <bounce/>
            <friction>
              <ode/>
            </friction>
            <contact>
              <ode/>
            </contact>
          </surface>
        </collision>
        <visual name='Wall_16_Visual_2'>
          <pose>0.597607 0 1.75 0 -0 0</pose>
          <geometry>
            <box>
              <size>1.17359 0.2 2.5</size>
            </box>
          </geometry>
          <material>
            <script>
              <uri>file://media/materials/scripts/gazebo.material</uri>
              <name>Gazebo/Grey</name>
            </script>
          </material>
        </visual>
        <collision name='Wall_16_Collision_2'>
          <geometry>
            <box>
              <size>1.17359 0.2 2.5</size>
            </box>
          </geometry>
          <pose>0.597607 0 1.75 0 -0 0</pose>
          <max_contacts>10</max_contacts>
          <surface>
            <bounce/>
            <friction>
              <ode/>
            </friction>
            <contact>
              <ode/>
            </contact>
          </surface>
        </collision>
        <visual name='Wall_16_Visual_3'>
          <pose>3.30944 0 1.75 0 -0 0</pose>
          <geometry>
            <box>
              <size>1.25008 0.2 2.5</size>
            </box>
          </geometry>
          <material>
            <script>
              <uri>file://media/materials/scripts/gazebo.material</uri>
              <name>Gazebo/Grey</name>
            </script>
          </material>
        </visual>
        <collision name='Wall_16_Collision_3'>
          <geometry>
            <box>
              <size>1.25008 0.2 2.5</size>
            </box>
          </geometry>
          <pose>3.30944 0 1.75 0 -0 0</pose>
          <max_contacts>10</max_contacts>
          <surface>
            <bounce/>
            <friction>
              <ode/>
            </friction>
            <contact>
              <ode/>
            </contact>
          </surface>
        </collision>
        <visual name='Wall_16_Visual_4'>
          <pose>-0.739186 0 2.75 0 -0 0</pose>
          <geometry>
            <box>
              <size>1.5 0.2 0.5</size>
            </box>
          </geometry>
          <material>
            <script>
              <uri>file://media/materials/scripts/gazebo.material</uri>
              <name>Gazebo/Grey</name>
            </script>
          </material>
        </visual>
        <collision name='Wall_16_Collision_4'>
          <geometry>
            <box>
              <size>1.5 0.2 0.5</size>
            </box>
          </geometry>
          <pose>-0.739186 0 2.75 0 -0 0</pose>
          <max_contacts>10</max_contacts>
          <surface>
            <bounce/>
            <friction>
              <ode/>
            </friction>
            <contact>
              <ode/>
            </contact>
          </surface>
        </collision>
        <visual name='Wall_16_Visual_5'>
          <pose>1.9344 0 2.75 0 -0 0</pose>
          <geometry>
            <box>
              <size>1.5 0.2 0.5</size>
            </box>
          </geometry>
          <material>
            <script>
              <uri>file://media/materials/scripts/gazebo.material</uri>
              <name>Gazebo/Grey</name>
            </script>
          </material>
        </visual>
        <collision name='Wall_16_Collision_5'>
          <geometry>
            <box>
              <size>1.5 0.2 0.5</size>
            </box>
          </geometry>
          <pose>1.9344 0 2.75 0 -0 0</pose>
          <max_contacts>10</max_contacts>
          <surface>
            <bounce/>
            <friction>
              <ode/>
            </friction>
            <contact>
              <ode/>
            </contact>
          </surface>
        </collision>
        <velocity_decay>
          <linear>0</linear>
          <angular>0</angular>
        </velocity_decay>
        <self_collide>0</self_collide>
        <kinematic>0</kinematic>
        <gravity>1</gravity>
      </link>
      <link name='Wall_18'>
        <collision name='Wall_18_Collision'>
          <geometry>
            <box>
              <size>5.89896 0.2 2.5</size>
            </box>
          </geometry>
          <pose>0 0 1.25 0 -0 0</pose>
          <max_contacts>10</max_contacts>
          <surface>
            <bounce/>
            <friction>
              <ode/>
            </friction>
            <contact>
              <ode/>
            </contact>
          </surface>
        </collision>
        <visual name='Wall_18_Visual'>
          <pose>0 0 1.25 0 -0 0</pose>
          <geometry>
            <box>
              <size>5.89896 0.2 2.5</size>
            </box>
          </geometry>
          <material>
            <script>
              <uri>file://media/materials/scripts/gazebo.material</uri>
              <name>Gazebo/Grey</name>
            </script>
          </material>
        </visual>
        <velocity_decay>
          <linear>0</linear>
          <angular>0</angular>
        </velocity_decay>
        <pose>2.81106 -2.29895 0 0 -0 3.14159</pose>
        <self_collide>0</self_collide>
        <kinematic>0</kinematic>
        <gravity>1</gravity>
      </link>
      <link name='Wall_5'>
        <collision name='Wall_5_Collision'>
          <geometry>
            <box>
              <size>4.95 0.2 3</size>
            </box>
          </geometry>
          <pose>0 0 1.5 0 -0 0</pose>
          <max_contacts>10</max_contacts>
          <surface>
            <bounce/>
            <friction>
              <ode/>
            </friction>
            <contact>
              <ode/>
            </contact>
          </surface>
        </collision>
        <visual name='Wall_5_Visual'>
          <pose>0 0 1.5 0 -0 0</pose>
          <geometry>
            <box>
              <size>4.95 0.2 3</size>
            </box>
          </geometry>
          <material>
            <script>
              <uri>file://media/materials/scripts/gazebo.material</uri>
              <name>Gazebo/Grey</name>
            </script>
          </material>
        </visual>
        <velocity_decay>
          <linear>0</linear>
          <angular>0</angular>
        </velocity_decay>
        <pose>15.549 -2.374 0 0 -0 1.5708</pose>
        <self_collide>0</self_collide>
        <kinematic>0</kinematic>
        <gravity>1</gravity>
      </link>
      <link name='Wall_7'>
        <collision name='Wall_7_Collision'>
          <geometry>
            <box>
              <size>3.2 0.2 3</size>
            </box>
          </geometry>
          <pose>0 0 1.5 0 -0 0</pose>
          <max_contacts>10</max_contacts>
          <surface>
            <bounce/>
            <friction>
              <ode/>
            </friction>
            <contact>
              <ode/>
            </contact>
          </surface>
        </collision>
        <visual name='Wall_7_Visual'>
          <pose>0 0 1.5 0 -0 0</pose>
          <geometry>
            <box>
              <size>3.2 0.2 3</size>
            </box>
          </geometry>
          <material>
            <script>
              <uri>file://media/materials/scripts/gazebo.material</uri>
              <name>Gazebo/Grey</name>
            </script>
          </material>
        </visual>
        <velocity_decay>
          <linear>0</linear>
          <angular>0</angular>
        </velocity_decay>
        <pose>14.021 -4.762 0 0 -0 0</pose>
        <self_collide>0</self_collide>
        <kinematic>0</kinematic>
        <gravity>1</gravity>
      </link>
      <link name='Wall_9'>
        <collision name='Wall_9_Collision'>
          <geometry>
            <box>
              <size>2.7 0.2 3</size>
            </box>
          </geometry>
          <pose>0 0 1.5 0 -0 0</pose>
          <max_contacts>10</max_contacts>
          <surface>
            <bounce/>
            <friction>
              <ode/>
            </friction>
            <contact>
              <ode/>
            </contact>
          </surface>
        </collision>
        <visual name='Wall_9_Visual'>
          <pose>0 0 1.5 0 -0 0</pose>
          <geometry>
            <box>
              <size>2.7 0.2 3</size>
            </box>
          </geometry>
          <material>
            <script>
              <uri>file://media/materials/scripts/gazebo.material</uri>
              <name>Gazebo/Grey</name>
            </script>
          </material>
        </visual>
        <velocity_decay>
          <linear>0</linear>
          <angular>0</angular>
        </velocity_decay>
        <pose>12.52 -3.511 0 0 -0 1.5708</pose>
        <self_collide>0</self_collide>
        <kinematic>0</kinematic>
        <gravity>1</gravity>
      </link>
      <static>1</static>
    </model>
    <model name='person_standing_0'>
      <link name='link'>
        <inertial>
          <pose>0 -0.1 0.95 0 -0 0</pose>
          <mass>80</mass>
          <inertia>
            <ixx>24.88</ixx>
            <ixy>0</ixy>
            <ixz>0</ixz>
            <iyy>25.73</iyy>
            <iyz>0</iyz>
            <izz>2.48</izz>
          </inertia>
        </inertial>
        <collision name='bottom'>
          <pose>0 -0.1 0.01 0 -0 0</pose>
          <geometry>
            <box>
              <size>0.5 0.35 0.02</size>
            </box>
          </geometry>
          <max_contacts>10</max_contacts>
          <surface>
            <bounce/>
            <friction>
              <ode/>
            </friction>
            <contact>
              <ode/>
            </contact>
          </surface>
        </collision>
        <collision name='person'>
          <pose>0 0 0.02 0.04 -0 0</pose>
          <geometry>
            <mesh>
              <uri>model://person_standing/meshes/standing.dae</uri>
            </mesh>
          </geometry>
          <max_contacts>10</max_contacts>
          <surface>
            <bounce/>
            <friction>
              <ode/>
            </friction>
            <contact>
              <ode/>
            </contact>
          </surface>
        </collision>
        <visual name='visual'>
          <pose>0 0 0.02 0.04 -0 0</pose>
          <geometry>
            <mesh>
              <uri>model://person_standing/meshes/standing.dae</uri>
            </mesh>
          </geometry>
        </visual>
        <velocity_decay>
          <linear>0</linear>
          <angular>0</angular>
        </velocity_decay>
        <self_collide>0</self_collide>
        <kinematic>0</kinematic>
        <gravity>1</gravity>
      </link>
      <pose>1 -8 0 0 -0 0</pose>
      <static>0</static>
    </model>
    <model name='person_standing_1'>
      <link name='link'>
        <inertial>
          <pose>0 -0.1 0.95 0 -0 0</pose>
          <mass>80</mass>
          <inertia>
            <ixx>24.88</ixx>
            <ixy>0</ixy>
            <ixz>0</ixz>
            <iyy>25.73</iyy>
            <iyz>0</iyz>
            <izz>2.48</izz>
          </inertia>
        </inertial>
        <collision name='bottom'>
          <pose>0 -0.1 0.01 0 -0 0</pose>
          <geometry>
            <box>
              <size>0.5 0.35 0.02</size>
            </box>
          </geometry>
          <max_contacts>10</max_contacts>
          <surface>
            <bounce/>
            <friction>
              <ode/>
            </friction>
            <contact>
              <ode/>
            </contact>
          </surface>
        </collision>
        <collision name='person'>
          <pose>0 0 0.02 0.04 -0 0</pose>
          <geometry>
            <mesh>
              <uri>model://person_standing/meshes/standing.dae</uri>
            </mesh>
          </geometry>
          <max_contacts>10</max_contacts>
          <surface>
            <bounce/>
            <friction>
              <ode/>
            </friction>
            <contact>
              <ode/>
            </contact>
          </surface>
        </collision>
        <visual name='visual'>
          <pose>0 0 0.02 0.04 -0 0</pose>
          <geometry>
            <mesh>
              <uri>model://person_standing/meshes/standing.dae</uri>
            </mesh>
          </geometry>
        </visual>
        <velocity_decay>
          <linear>0</linear>
          <angular>0</angular>
        </velocity_decay>
        <self_collide>0</self_collide>
        <kinematic>0</kinematic>
        <gravity>1</gravity>
      </link>
      <pose>6.58102 -8 0 0 -0 0</pose>
      <static>0</static>
    </model>
    <model name='person_standing_2'>
      <link name='link'>
        <inertial>
          <pose>0 -0.1 0.95 0 -0 0</pose>
          <mass>80</mass>
          <inertia>
            <ixx>24.88</ixx>
            <ixy>0</ixy>
            <ixz>0</ixz>
            <iyy>25.73</iyy>
            <iyz>0</iyz>
            <izz>2.48</izz>
          </inertia>
        </inertial>
        <collision name='bottom'>
          <pose>0 -0.1 0.01 0 -0 0</pose>
          <geometry>
            <box>
              <size>0.5 0.35 0.02</size>
            </box>
          </geometry>
          <max_contacts>10</max_contacts>
          <surface>
            <bounce/>
            <friction>
              <ode/>
            </friction>
            <contact>
              <ode/>
            </contact>
          </surface>
        </collision>
        <collision name='person'>
          <pose>0 0 0.02 0.04 -0 0</pose>
          <geometry>
            <mesh>
              <uri>model://person_standing/meshes/standing.dae</uri>
            </mesh>
          </geometry>
          <max_contacts>10</max_contacts>
          <surface>
            <bounce/>
            <friction>
              <ode/>
            </friction>
            <contact>
              <ode/>
            </contact>
          </surface>
        </collision>
        <visual name='visual'>
          <pose>0 0 0.02 0.04 -0 0</pose>
          <geometry>
            <mesh>
              <uri>model://person_standing/meshes/standing.dae</uri>
            </mesh>
          </geometry>
        </visual>
        <velocity_decay>
          <linear>0</linear>
          <angular>0</angular>
        </velocity_decay>
        <self_collide>0</self_collide>
        <kinematic>0</kinematic>
        <gravity>1</gravity>
      </link>
      <pose>1 -1 0 0 -0 0</pose>
      <static>0</static>
    </model>
    <model name='person_standing_3'>
      <link name='link'>
        <inertial>
          <pose>0 -0.1 0.95 0 -0 0</pose>
          <mass>80</mass>
          <inertia>
            <ixx>24.88</ixx>
            <ixy>0</ixy>
            <ixz>0</ixz>
            <iyy>25.73</iyy>
            <iyz>0</iyz>
            <izz>2.48</izz>
          </inertia>
        </inertial>
        <collision name='bottom'>
          <pose>0 -0.1 0.01 0 -0 0</pose>
          <geometry>
            <box>
              <size>0.5 0.35 0.02</size>
            </box>
          </geometry>
          <max_contacts>10</max_contacts>
          <surface>
            <bounce/>
            <friction>
              <ode/>
            </friction>
            <contact>
              <ode/>
            </contact>
          </surface>
        </collision>
        <collision name='person'>
          <pose>0 0 0.02 0.04 -0 0</pose>
          <geometry>
            <mesh>
              <uri>model://person_standing/meshes/standing.dae</uri>
            </mesh>
          </geometry>
          <max_contacts>10</max_contacts>
          <surface>
            <bounce/>
            <friction>
              <ode/>
            </friction>
            <contact>
              <ode/>
            </contact>
          </surface>
        </collision>
        <visual name='visual'>
          <pose>0 0 0.02 0.04 -0 0</pose>
          <geometry>
            <mesh>
              <uri>model://person_standing/meshes/standing.dae</uri>
            </mesh>
          </geometry>
        </visual>
        <velocity_decay>
          <linear>0</linear>
          <angular>0</angular>
        </velocity_decay>
        <self_collide>0</self_collide>
        <kinematic>0</kinematic>
        <gravity>1</gravity>
      </link>
      <pose>14 -4 0 0 -0 0</pose>
      <static>0</static>
    </model>
    <model name='person_standing_4'>
      <link name='link'>
        <inertial>
          <pose>0 -0.1 0.95 0 -0 0</pose>
          <mass>80</mass>
          <inertia>
            <ixx>24.88</ixx>
            <ixy>0</ixy>
            <ixz>0</ixz>
            <iyy>25.73</iyy>
            <iyz>0</iyz>
            <izz>2.48</izz>
          </inertia>
        </inertial>
        <collision name='bottom'>
          <pose>0 -0.1 0.01 0 -0 0</pose>
          <geometry>
            <box>
              <size>0.5 0.35 0.02</size>
            </box>
          </geometry>
          <max_contacts>10</max_contacts>
          <surface>
            <bounce/>
            <friction>
              <ode/>
            </friction>
            <contact>
              <ode/>
            </contact>
          </surface>
        </collision>
        <collision name='person'>
          <pose>0 0 0.02 0.04 -0 0</pose>
          <geometry>
            <mesh>
              <uri>model://person_standing/meshes/standing.dae</uri>
            </mesh>
          </geometry>
          <max_contacts>10</max_contacts>
          <surface>
            <bounce/>
            <friction>
              <ode/>
            </friction>
            <contact>
              <ode/>
            </contact>
          </surface>
        </collision>
        <visual name='visual'>
          <pose>0 0 0.02 0.04 -0 0</pose>
          <geometry>
            <mesh>
              <uri>model://person_standing/meshes/standing.dae</uri>
            </mesh>
          </geometry>
        </visual>
        <velocity_decay>
          <linear>0</linear>
          <angular>0</angular>
        </velocity_decay>
        <self_collide>0</self_collide>
        <kinematic>0</kinematic>
        <gravity>1</gravity>
      </link>
      <pose>2 -8 0 0 -0 0</pose>
      <static>0</static>
    </model>
    <state world_name='default'>
      <sim_time>152 373000000</sim_time>
      <real_time>153 960096671</real_time>
      <wall_time>1490967384 355174583</wall_time>
      <model name='ground_plane'>
        <pose>0 0 0 0 -0 0</pose>
        <link name='link'>
          <pose>0 0 0 0 -0 0</pose>
          <velocity>0 0 0 0 -0 0</velocity>
          <acceleration>0 0 0 0 -0 0</acceleration>
          <wrench>0 0 0 0 -0 0</wrench>
        </link>
      </model>
    </state>
    <model name='my_robot'>
      <pose>4 -8 0 0 -0 0</pose>
      <static>0</static>
      <link name='chassis'>
        <inertial>
          <mass>30</mass>
          <inertia>
            <ixx>0.3338</ixx>
            <ixy>0</ixy>
            <ixz>0</ixz>
            <iyy>0.4783</iyy>
            <iyz>0</iyz>
            <izz>0.3338</izz>
          </inertia>
        </inertial>
        <collision name='collision'>
          <geometry>
            <box>
              <size>0.501 0.4 0.19</size>
            </box>
          </geometry>
          <max_contacts>10</max_contacts>
          <surface>
            <bounce/>
            <friction>
              <ode/>
            </friction>
            <contact>
              <ode/>
            </contact>
          </surface>
        </collision>
        <visual name='visual'>
          <geometry>
            <mesh>
              <uri>model://pioneer3at/meshes/chassis.dae</uri>
            </mesh>
          </geometry>
        </visual>
        <velocity_decay>
          <linear>0</linear>
          <angular>0</angular>
        </velocity_decay>
        <self_collide>0</self_collide>
        <kinematic>0</kinematic>
        <gravity>1</gravity>
      </link>
      <link name='right_front_wheel'>
        <pose>0.125 -0.201 -0.06 1.5707 -0 0</pose>
        <collision name='collision'>
          <geometry>
            <cylinder>
              <radius>0.11</radius>
              <length>0.075</length>
            </cylinder>
          </geometry>
          <surface>
            <friction>
              <ode>
                <mu>1</mu>
                <mu2>1</mu2>
                <slip1>0.5</slip1>
                <slip2>0</slip2>
              </ode>
            </friction>
            <bounce/>
            <contact>
              <ode/>
            </contact>
          </surface>
          <max_contacts>10</max_contacts>
        </collision>
        <visual name='visual'>
          <geometry>
            <mesh>
              <uri>model://pioneer3at/meshes/wheel.dae</uri>
            </mesh>
          </geometry>
        </visual>
        <velocity_decay>
          <linear>0</linear>
          <angular>0</angular>
        </velocity_decay>
        <self_collide>0</self_collide>
        <inertial>
          <inertia>
            <ixx>1</ixx>
            <ixy>0</ixy>
            <ixz>0</ixz>
            <iyy>1</iyy>
            <iyz>0</iyz>
            <izz>1</izz>
          </inertia>
          <mass>1</mass>
        </inertial>
        <kinematic>0</kinematic>
        <gravity>1</gravity>
      </link>
      <link name='left_front_wheel'>
        <pose>0.125 0.201 -0.06 1.5707 -0 0</pose>
        <collision name='collision'>
          <geometry>
            <cylinder>
              <radius>0.11</radius>
              <length>0.075</length>
            </cylinder>
          </geometry>
          <surface>
            <friction>
              <ode>
                <mu>1</mu>
                <mu2>1</mu2>
                <slip1>0.5</slip1>
                <slip2>0</slip2>
              </ode>
            </friction>
            <bounce/>
            <contact>
              <ode/>
            </contact>
          </surface>
          <max_contacts>10</max_contacts>
        </collision>
        <visual name='visual'>
          <geometry>
            <mesh>
              <uri>model://pioneer3at/meshes/wheel.dae</uri>
            </mesh>
          </geometry>
        </visual>
        <velocity_decay>
          <linear>0</linear>
          <angular>0</angular>
        </velocity_decay>
        <self_collide>0</self_collide>
        <inertial>
          <inertia>
            <ixx>1</ixx>
            <ixy>0</ixy>
            <ixz>0</ixz>
            <iyy>1</iyy>
            <iyz>0</iyz>
            <izz>1</izz>
          </inertia>
          <mass>1</mass>
        </inertial>
        <kinematic>0</kinematic>
        <gravity>1</gravity>
      </link>
      <link name='c1'>
        <pose>0 0 0.3 0 -0 0</pose>
        <inertial>
          <mass>1</mass>
          <inertia>
            <ixx>0.3338</ixx>
            <ixy>0</ixy>
            <ixz>0</ixz>
            <iyy>0.4783</iyy>
            <iyz>0</iyz>
            <izz>0.3338</izz>
          </inertia>
        </inertial>
        <collision name='collision'>
          <geometry>
            <box>
              <size>0.4 0.4 0.02</size>
            </box>
          </geometry>
          <max_contacts>10</max_contacts>
          <surface>
            <bounce/>
            <friction>
              <ode/>
            </friction>
            <contact>
              <ode/>
            </contact>
          </surface>
        </collision>
        <visual name='visual'>
          <geometry>
            <box>
              <size>0.4 0.4 0.02</size>
            </box>
          </geometry>
        </visual>
        <velocity_decay>
          <linear>0</linear>
          <angular>0</angular>
        </velocity_decay>
        <self_collide>0</self_collide>
        <kinematic>0</kinematic>
        <gravity>1</gravity>
      </link>
      <joint name='c1_joint' type='revolute'>
        <child>c1</child>
        <parent>chassis</parent>
        <axis>
          <xyz>0 0 1</xyz>
          <limit>
            <upper>0</upper>
            <lower>0</lower>
          </limit>
        </axis>
      </joint>
      <link name='c2'>
        <pose>0 0 0.6 0 -0 0</pose>
        <inertial>
          <mass>1</mass>
          <inertia>
            <ixx>0.3338</ixx>
            <ixy>0</ixy>
            <ixz>0</ixz>
            <iyy>0.4783</iyy>
            <iyz>0</iyz>
            <izz>0.3338</izz>
          </inertia>
        </inertial>
        <collision name='collision'>
          <geometry>
            <box>
              <size>0.4 0.4 0.02</size>
            </box>
          </geometry>
          <max_contacts>10</max_contacts>
          <surface>
            <bounce/>
            <friction>
              <ode/>
            </friction>
            <contact>
              <ode/>
            </contact>
          </surface>
        </collision>
        <visual name='visual'>
          <geometry>
            <box>
              <size>0.4 0.4 0.02</size>
            </box>
          </geometry>
        </visual>
        <velocity_decay>
          <linear>0</linear>
          <angular>0</angular>
        </velocity_decay>
        <self_collide>0</self_collide>
        <kinematic>0</kinematic>
        <gravity>1</gravity>
      </link>
      <joint name='c2_joint' type='revolute'>
        <child>c2</child>
        <parent>chassis</parent>
        <axis>
          <xyz>0 0 1</xyz>
          <limit>
            <upper>0</upper>
            <lower>0</lower>
          </limit>
        </axis>
      </joint>
      <link name='c3'>
        <pose>0 0 0.9 0 -0 0</pose>
        <inertial>
          <mass>1</mass>
          <inertia>
            <ixx>0.3338</ixx>
            <ixy>0</ixy>
            <ixz>0</ixz>
            <iyy>0.4783</iyy>
            <iyz>0</iyz>
            <izz>0.3338</izz>
          </inertia>
        </inertial>
        <collision name='collision'>
          <geometry>
            <box>
              <size>0.4 0.4 0.02</size>
            </box>
          </geometry>
          <max_contacts>10</max_contacts>
          <surface>
            <bounce/>
            <friction>
              <ode/>
            </friction>
            <contact>
              <ode/>
            </contact>
          </surface>
        </collision>
        <visual name='visual'>
          <geometry>
            <box>
              <size>0.4 0.4 0.02</size>
            </box>
          </geometry>
        </visual>
        <velocity_decay>
          <linear>0</linear>
          <angular>0</angular>
        </velocity_decay>
        <self_collide>0</self_collide>
        <kinematic>0</kinematic>
        <gravity>1</gravity>
      </link>
      <joint name='c3_joint' type='revolute'>
        <child>c3</child>
        <parent>chassis</parent>
        <axis>
          <xyz>0 0 1</xyz>
          <limit>
            <upper>0</upper>
            <lower>0</lower>
          </limit>
        </axis>
      </joint>
      <link name='c4'>
        <pose>0.1 0.13 0.46 0 -0 0</pose>
        <inertial>
          <mass>1</mass>
          <inertia>
            <ixx>0.3338</ixx>
            <ixy>0</ixy>
            <ixz>0</ixz>
            <iyy>0.4783</iyy>
            <iyz>0</iyz>
            <izz>0.3338</izz>
          </inertia>
        </inertial>
        <collision name='collision'>
          <geometry>
            <box>
              <size>0.02 0.02 0.9</size>
            </box>
          </geometry>
          <max_contacts>10</max_contacts>
          <surface>
            <bounce/>
            <friction>
              <ode/>
            </friction>
            <contact>
              <ode/>
            </contact>
          </surface>
        </collision>
        <visual name='visual'>
          <geometry>
            <box>
              <size>0.02 0.02 0.9</size>
            </box>
          </geometry>
        </visual>
        <velocity_decay>
          <linear>0</linear>
          <angular>0</angular>
        </velocity_decay>
        <self_collide>0</self_collide>
        <kinematic>0</kinematic>
        <gravity>1</gravity>
      </link>
      <joint name='c4_joint' type='revolute'>
        <child>c4</child>
        <parent>chassis</parent>
        <axis>
          <xyz>0 0 1</xyz>
          <limit>
            <upper>0</upper>
            <lower>0</lower>
          </limit>
        </axis>
      </joint>
      <link name='c5'>
        <pose>-0.1 0.13 0.46 0 -0 0</pose>
        <inertial>
          <mass>1</mass>
          <inertia>
            <ixx>0.3338</ixx>
            <ixy>0</ixy>
            <ixz>0</ixz>
            <iyy>0.4783</iyy>
            <iyz>0</iyz>
            <izz>0.3338</izz>
          </inertia>
        </inertial>
        <collision name='collision'>
          <geometry>
            <box>
              <size>0.02 0.02 0.9</size>
            </box>
          </geometry>
          <max_contacts>10</max_contacts>
          <surface>
            <bounce/>
            <friction>
              <ode/>
            </friction>
            <contact>
              <ode/>
            </contact>
          </surface>
        </collision>
        <visual name='visual'>
          <geometry>
            <box>
              <size>0.02 0.02 0.9</size>
            </box>
          </geometry>
        </visual>
        <velocity_decay>
          <linear>0</linear>
          <angular>0</angular>
        </velocity_decay>
        <self_collide>0</self_collide>
        <kinematic>0</kinematic>
        <gravity>1</gravity>
      </link>
      <joint name='c5_joint' type='revolute'>
        <child>c5</child>
        <parent>chassis</parent>
        <axis>
          <xyz>0 0 1</xyz>
          <limit>
            <upper>0</upper>
            <lower>0</lower>
          </limit>
        </axis>
      </joint>
      <link name='c6'>
        <pose>-0.1 -0.13 0.46 0 -0 0</pose>
        <inertial>
          <mass>1</mass>
          <inertia>
            <ixx>0.3338</ixx>
            <ixy>0</ixy>
            <ixz>0</ixz>
            <iyy>0.4783</iyy>
            <iyz>0</iyz>
            <izz>0.3338</izz>
          </inertia>
        </inertial>
        <collision name='collision'>
          <geometry>
            <box>
              <size>0.02 0.02 0.9</size>
            </box>
          </geometry>
          <max_contacts>10</max_contacts>
          <surface>
            <bounce/>
            <friction>
              <ode/>
            </friction>
            <contact>
              <ode/>
            </contact>
          </surface>
        </collision>
        <visual name='visual'>
          <geometry>
            <box>
              <size>0.02 0.02 0.9</size>
            </box>
          </geometry>
        </visual>
        <velocity_decay>
          <linear>0</linear>
          <angular>0</angular>
        </velocity_decay>
        <self_collide>0</self_collide>
        <kinematic>0</kinematic>
        <gravity>1</gravity>
      </link>
      <joint name='c6_joint' type='revolute'>
        <child>c6</child>
        <parent>chassis</parent>
        <axis>
          <xyz>0 0 1</xyz>
          <limit>
            <upper>0</upper>
            <lower>0</lower>
          </limit>
        </axis>
      </joint>
      <link name='c7'>
        <pose>0.1 -0.13 0.46 0 -0 0</pose>
        <inertial>
          <mass>1</mass>
          <inertia>
            <ixx>0.3338</ixx>
            <ixy>0</ixy>
            <ixz>0</ixz>
            <iyy>0.4783</iyy>
            <iyz>0</iyz>
            <izz>0.3338</izz>
          </inertia>
        </inertial>
        <collision name='collision'>
          <geometry>
            <box>
              <size>0.02 0.02 0.9</size>
            </box>
          </geometry>
          <max_contacts>10</max_contacts>
          <surface>
            <bounce/>
            <friction>
              <ode/>
            </friction>
            <contact>
              <ode/>
            </contact>
          </surface>
        </collision>
        <visual name='visual'>
          <geometry>
            <box>
              <size>0.02 0.02 0.9</size>
            </box>
          </geometry>
        </visual>
        <velocity_decay>
          <linear>0</linear>
          <angular>0</angular>
        </velocity_decay>
        <self_collide>0</self_collide>
        <kinematic>0</kinematic>
        <gravity>1</gravity>
      </link>
      <joint name='c7_joint' type='revolute'>
        <child>c7</child>
        <parent>chassis</parent>
        <axis>
          <xyz>0 0 1</xyz>
          <limit>
            <upper>0</upper>
            <lower>0</lower>
          </limit>
        </axis>
      </joint>
      <link name='right_rear_wheel'>
        <pose>-0.125 -0.201 -0.06 1.5707 -0 0</pose>
        <collision name='collision'>
          <geometry>
            <cylinder>
              <radius>0.11</radius>
              <length>0.075</length>
            </cylinder>
          </geometry>
          <surface>
            <friction>
              <ode>
                <mu>1</mu>
                <mu2>1</mu2>
                <slip1>0.5</slip1>
                <slip2>0</slip2>
              </ode>
            </friction>
            <bounce/>
            <contact>
              <ode/>
            </contact>
          </surface>
          <max_contacts>10</max_contacts>
        </collision>
        <visual name='visual'>
          <geometry>
            <mesh>
              <uri>model://pioneer3at/meshes/wheel.dae</uri>
            </mesh>
          </geometry>
        </visual>
        <velocity_decay>
          <linear>0</linear>
          <angular>0</angular>
        </velocity_decay>
        <self_collide>0</self_collide>
        <inertial>
          <inertia>
            <ixx>1</ixx>
            <ixy>0</ixy>
            <ixz>0</ixz>
            <iyy>1</iyy>
            <iyz>0</iyz>
            <izz>1</izz>
          </inertia>
          <mass>1</mass>
        </inertial>
        <kinematic>0</kinematic>
        <gravity>1</gravity>
      </link>
      <link name='left_rear_wheel'>
        <pose>-0.125 0.201 -0.06 1.5707 -0 0</pose>
        <collision name='collision'>
          <geometry>
            <cylinder>
              <radius>0.11</radius>
              <length>0.075</length>
            </cylinder>
          </geometry>
          <surface>
            <friction>
              <ode>
                <mu>1</mu>
                <mu2>1</mu2>
                <slip1>0.5</slip1>
                <slip2>0</slip2>
              </ode>
            </friction>
            <bounce/>
            <contact>
              <ode/>
            </contact>
          </surface>
          <max_contacts>10</max_contacts>
        </collision>
        <visual name='visual'>
          <geometry>
            <mesh>
              <uri>model://pioneer3at/meshes/wheel.dae</uri>
            </mesh>
          </geometry>
        </visual>
        <velocity_decay>
          <linear>0</linear>
          <angular>0</angular>
        </velocity_decay>
        <self_collide>0</self_collide>
        <inertial>
          <inertia>
            <ixx>1</ixx>
            <ixy>0</ixy>
            <ixz>0</ixz>
            <iyy>1</iyy>
            <iyz>0</iyz>
            <izz>1</izz>
          </inertia>
          <mass>1</mass>
        </inertial>
        <kinematic>0</kinematic>
        <gravity>1</gravity>
      </link>
      <joint name='right_front' type='revolute'>
        <pose>0 0 0 0 -0 0</pose>
        <child>right_front_wheel</child>
        <parent>chassis</parent>
        <axis>
          <xyz>0 1 0</xyz>
          <limit>
            <lower>-1e+16</lower>
            <upper>1e+16</upper>
          </limit>
        </axis>
      </joint>
      <joint name='right_rear' type='revolute'>
        <pose>0 0 0 0 -0 0</pose>
        <child>right_rear_wheel</child>
        <parent>chassis</parent>
        <axis>
          <xyz>0 1 0</xyz>
          <limit>
            <lower>-1e+16</lower>
            <upper>1e+16</upper>
          </limit>
        </axis>
      </joint>
      <joint name='left_front' type='revolute'>
        <pose>0 0 0 0 -0 0</pose>
        <child>left_front_wheel</child>
        <parent>chassis</parent>
        <axis>
          <xyz>0 1 0</xyz>
          <limit>
            <lower>-1e+16</lower>
            <upper>1e+16</upper>
          </limit>
        </axis>
      </joint>
      <joint name='left_rear' type='revolute'>
        <pose>0 0 0 0 -0 0</pose>
        <child>left_rear_wheel</child>
        <parent>chassis</parent>
        <axis>
          <xyz>0 1 0</xyz>
          <limit>
            <lower>-1e+16</lower>
            <upper>1e+16</upper>
          </limit>
        </axis>
      </joint>

  <plugin name="skid_steer_drive_controller" filename="libgazebo_ros_skid_steer_drive.so">
    <updateRate>100.0</updateRate>
    <robotNamespace>/</robotNamespace>
    <leftFrontJoint>left_front</leftFrontJoint>
    <rightFrontJoint>right_front</rightFrontJoint>
    <leftRearJoint>left_rear</leftRearJoint>
    <rightRearJoint>right_rear</rightRearJoint>
    <wheelSeparation>0.4</wheelSeparation>
    <wheelDiameter>0.11</wheelDiameter>
    <robotBaseFrame>base_link</robotBaseFrame>
    <commandTopic>/Pioneer3AT/cmd_vel</commandTopic>
    <odometryTopic>/Pioneer3AT/odom</odometryTopic>
    <torque>5</torque>
    <topicName>cmd_vel</topicName>
    <broadcastTF>1</broadcastTF>
  </plugin>


      <link name='hokuyo'>
        <inertial>
          <mass>0.1</mass>
          <inertia>
            <ixx>1</ixx>
            <ixy>0</ixy>
            <ixz>0</ixz>
            <iyy>1</iyy>
            <iyz>0</iyz>
            <izz>1</izz>
          </inertia>
        </inertial>
        <visual name='visual'>
          <geometry>
            <mesh>
              <uri>model://hokuyo/meshes/hokuyo.dae</uri>
            </mesh>
          </geometry>
        </visual>
        <sensor name='head_hokuyo_sensor' type='ray'>
          <pose>0.15 0 0.13 0 -0 0</pose>
          <ray>
            <scan>
              <horizontal>
                <samples>640</samples>
                <resolution>1</resolution>
                <min_angle>-1.57</min_angle>
                <max_angle>1.57</max_angle>
              </horizontal>
            </scan>
            <range>
              <min>0.08</min>
              <max>10</max>
              <resolution>0.01</resolution>
            </range>
          </ray>
          <plugin name='gazebo_ros_head_hokuyo_controller' filename='libgazebo_ros_laser.so'>
        <topicName>/laser/scan</topicName>
        <frameName>hokuyo_link</frameName>
          </plugin>
          <always_on>1</always_on>
          <update_rate>30</update_rate>
          <visualize>1</visualize>
        </sensor>
        <velocity_decay>
          <linear>0</linear>
          <angular>0</angular>
        </velocity_decay>
        <self_collide>0</self_collide>
        <kinematic>0</kinematic>
        <gravity>1</gravity>
      </link>
      <joint name='hokuyo_joint' type='revolute'>
        <child>hokuyo</child>
        <parent>chassis</parent>
        <axis>
          <xyz>0 0 1</xyz>
          <limit>
            <upper>0</upper>
            <lower>0</lower>
          </limit>
        </axis>
      </joint>



      <link name='kinect::link'>
        <inertial>
          <mass>0.1</mass>
          <inertia>
            <ixx>1</ixx>
            <ixy>0</ixy>
            <ixz>0</ixz>
            <iyy>1</iyy>
            <iyz>0</iyz>
            <izz>1</izz>
          </inertia>
        </inertial>
        <collision name='collision'>
          <geometry>
            <box>
              <size>0.073 0.276 0.072</size>
            </box>
          </geometry>
          <max_contacts>10</max_contacts>
          <surface>
            <bounce/>
            <friction>
              <ode/>
            </friction>
            <contact>
              <ode/>
            </contact>
          </surface>
        </collision>
        <visual name='visual'>
          <geometry>
            <mesh>
              <uri>model://kinect/meshes/kinect.dae</uri>
            </mesh>
          </geometry>
        </visual>
        <velocity_decay>
          <linear>0</linear>
          <angular>0</angular>
        </velocity_decay>
        <pose>0.17 0 0.65 0 -0 0</pose>
        <self_collide>0</self_collide>
        <kinematic>0</kinematic>
        <gravity>1</gravity>
        <sensor name='camera' type='depth'>
          <always_on>1</always_on>
          <update_rate>20</update_rate>
          <camera name='__default__'>
            <horizontal_fov>1.0472</horizontal_fov>
            <image>
              <format>R8G8B8</format>
              <width>640</width>
              <height>480</height>
            </image>
            <clip>
              <near>0.05</near>
              <far>8</far>
            </clip>
          </camera>
          <plugin name='kinect_camera_controller' filename='libgazebo_ros_openni_kinect.so'>
            <cameraName>camera</cameraName>
            <alwaysOn>true</alwaysOn>
            <updateRate>10</updateRate>
            <imageTopicName>rgb/image_raw</imageTopicName>
            <depthImageTopicName>depth/image_raw</depthImageTopicName>
            <pointCloudTopicName>depth/points</pointCloudTopicName>
            <cameraInfoTopicName>rgb/camera_info</cameraInfoTopicName>
            <depthImageCameraInfoTopicName>depth/camera_info</depthImageCameraInfoTopicName>
            <frameName>camera_depth_optical_frame</frameName>
            <baseline>0.1</baseline>
            <distortion_k1>0.0</distortion_k1>
            <distortion_k2>0.0</distortion_k2>
            <distortion_k3>0.0</distortion_k3>
            <distortion_t1>0.0</distortion_t1>
            <distortion_t2>0.0</distortion_t2>
            <pointCloudCutoff>0.4</pointCloudCutoff>
            <pointCloudCutoffMax>5</pointCloudCutoffMax>
            <robotNamespace>/</robotNamespace>
          </plugin>
          <pose>-0.118 0 0.288 0 -0 0</pose>
        </sensor>

      </link>



      <joint name='kinect_joint' type='revolute'>
        <child>kinect::link</child>
        <parent>chassis</parent>
        <axis>
          <xyz>0 0 1</xyz>
          <limit>
            <upper>0</upper>
            <lower>0</lower>
          </limit>
        </axis>
      </joint>

    </model>
  </world>
</sdf>
